<?xml version="1.0" ?>
<robot name="robocop" xmlns:xacro="http://www.ros.org/wiki/xacro">

<xacro:include filename="$(find robocop_description)/urdf/materials.xacro" />
<xacro:include filename="$(find robocop_description)/urdf/robocop.trans" />

<xacro:include filename="$(find robocop_description)/gazebo/robocop_materials.gazebo" />
<xacro:include filename="$(find robocop_description)/gazebo/robocop_physics.gazebo" />
<xacro:include filename="$(find robocop_description)/gazebo/robocop_plugins.gazebo" />

<link name="base_link">
  <inertial>
    <origin xyz="-0.0013001515328987126 -0.0017028571084608795 0.08695702362938688" rpy="0 0 0"/>
    <mass value="0.518865961499241"/>
    <inertia ixx="0.002526" iyy="0.001389" izz="0.003913" ixy="-0.0" iyz="0.0" ixz="0.0"/>
  </inertial>
  <visual>
    <origin xyz="0 0 0" rpy="0 0 0"/>
    <geometry>
      <mesh filename="package://robocop_description/meshes/base_link.stl" scale="0.001 0.001 0.001"/>
    </geometry>
    <material name="plstico_mate_verde"/>
  </visual>
  <collision>
    <origin xyz="0 0 0" rpy="0 0 0"/>
    <geometry>
      <mesh filename="package://robocop_description/meshes/base_link.stl" scale="0.001 0.001 0.001"/>
    </geometry>
  </collision>
</link>

<link name="soporteCamara_v2_1">
  <inertial>
    <origin xyz="0.030999848466254507 0.03309637231806288 0.0028238611176833878" rpy="0 0 0"/>
    <mass value="0.3066668323515448"/>
    <inertia ixx="0.000213" iyy="0.000189" izz="0.0004" ixy="0.0" iyz="-4e-06" ixz="0.0"/>
  </inertial>
  <visual>
    <origin xyz="0.0323 -0.088295 -0.089446" rpy="0 0 0"/>
    <geometry>
      <mesh filename="package://robocop_description/meshes/soporteCamara_v2_1.stl" scale="0.001 0.001 0.001"/>
    </geometry>
    <material name="plstico_mate_verde"/>
  </visual>
  <collision>
    <origin xyz="0.0323 -0.088295 -0.089446" rpy="0 0 0"/>
    <geometry>
      <mesh filename="package://robocop_description/meshes/soporteCamara_v2_1.stl" scale="0.001 0.001 0.001"/>
    </geometry>
  </collision>
</link>

<link name="depthCamera_v1_1">
  <inertial>
    <origin xyz="1.2977962637454295e-05 -0.013660026041507928 0.013865360448962805" rpy="0 0 0"/>
    <mass value="1.4328260381707594"/>
    <inertia ixx="0.000283" iyy="0.003111" izz="0.00318" ixy="-0.0" iyz="-5e-06" ixz="-0.0"/>
  </inertial>
  <visual>
    <origin xyz="0.0013 -0.16362 -0.097912" rpy="0 0 0"/>
    <geometry>
      <mesh filename="package://robocop_description/meshes/depthCamera_v1_1.stl" scale="0.001 0.001 0.001"/>
    </geometry>
    <material name="acero_satinado"/>
  </visual>
  <collision>
    <origin xyz="0.0013 -0.16362 -0.097912" rpy="0 0 0"/>
    <geometry>
      <mesh filename="package://robocop_description/meshes/depthCamera_v1_1.stl" scale="0.001 0.001 0.001"/>
    </geometry>
  </collision>
</link>

<link name="soporteElectronica_v7_1">
  <inertial>
    <origin xyz="0.07505332529276447 0.055002349444357466 0.04613612305196724" rpy="0 0 0"/>
    <mass value="1.7280541618979528"/>
    <inertia ixx="0.002669" iyy="0.008802" izz="0.009606" ixy="0.0" iyz="-0.0" ixz="2.2e-05"/>
  </inertial>
  <visual>
    <origin xyz="0.077 0.056705 -0.089446" rpy="0 0 0"/>
    <geometry>
      <mesh filename="package://robocop_description/meshes/soporteElectronica_v7_1.stl" scale="0.001 0.001 0.001"/>
    </geometry>
    <material name="plstico_mate_verde"/>
  </visual>
  <collision>
    <origin xyz="0.077 0.056705 -0.089446" rpy="0 0 0"/>
    <geometry>
      <mesh filename="package://robocop_description/meshes/soporteElectronica_v7_1.stl" scale="0.001 0.001 0.001"/>
    </geometry>
  </collision>
</link>

<link name="basePrincipal_v4_1">
  <inertial>
    <origin xyz="0.0674998484671067 -0.09000047986017973 -0.0009996705328835231" rpy="0 0 0"/>
    <mass value="0.44398234905881495"/>
    <inertia ixx="0.001466" iyy="0.000868" izz="0.002334" ixy="-0.0" iyz="0.0" ixz="0.0"/>
  </inertial>
  <visual>
    <origin xyz="0.0688 -0.088295 -0.084446" rpy="0 0 0"/>
    <geometry>
      <mesh filename="package://robocop_description/meshes/basePrincipal_v4_1.stl" scale="0.001 0.001 0.001"/>
    </geometry>
    <material name="aluminio_pulido"/>
  </visual>
  <collision>
    <origin xyz="0.0688 -0.088295 -0.084446" rpy="0 0 0"/>
    <geometry>
      <mesh filename="package://robocop_description/meshes/basePrincipal_v4_1.stl" scale="0.001 0.001 0.001"/>
    </geometry>
  </collision>
</link>

<link name="baseRuedas_v3__1__1">
  <inertial>
    <origin xyz="-0.0029159415133633293 -0.0001620061829542209 -0.035178126681478745" rpy="0 0 0"/>
    <mass value="0.25465013251117524"/>
    <inertia ixx="0.001194" iyy="0.000128" izz="0.001072" ixy="-0.0" iyz="4e-06" ixz="-9e-06"/>
  </inertial>
  <visual>
    <origin xyz="0.0763 0.001705 -0.082446" rpy="0 0 0"/>
    <geometry>
      <mesh filename="package://robocop_description/meshes/baseRuedas_v3__1__1.stl" scale="0.001 0.001 0.001"/>
    </geometry>
    <material name="aluminio_pulido"/>
  </visual>
  <collision>
    <origin xyz="0.0763 0.001705 -0.082446" rpy="0 0 0"/>
    <geometry>
      <mesh filename="package://robocop_description/meshes/baseRuedas_v3__1__1.stl" scale="0.001 0.001 0.001"/>
    </geometry>
  </collision>
</link>

<link name="baseRuedas_v3_1">
  <inertial>
    <origin xyz="0.003915638447583289 0.0001610464625932985 -0.035178126681478884" rpy="0 0 0"/>
    <mass value="0.25465013251117524"/>
    <inertia ixx="0.001194" iyy="0.000128" izz="0.001072" ixy="-0.0" iyz="-4e-06" ixz="9e-06"/>
  </inertial>
  <visual>
    <origin xyz="-0.0737 0.001705 -0.082446" rpy="0 0 0"/>
    <geometry>
      <mesh filename="package://robocop_description/meshes/baseRuedas_v3_1.stl" scale="0.001 0.001 0.001"/>
    </geometry>
    <material name="aluminio_pulido"/>
  </visual>
  <collision>
    <origin xyz="-0.0737 0.001705 -0.082446" rpy="0 0 0"/>
    <geometry>
      <mesh filename="package://robocop_description/meshes/baseRuedas_v3_1.stl" scale="0.001 0.001 0.001"/>
    </geometry>
  </collision>
</link>

<link name="soportePantalla_v11_1">
  <inertial>
    <origin xyz="0.0310236963188651 -0.054820451543081225 0.04169322204509168" rpy="0 0 0"/>
    <mass value="1.4723320792485302"/>
    <inertia ixx="0.003175" iyy="0.003919" izz="0.002641" ixy="-1e-06" iyz="0.000192" ixz="1e-06"/>
  </inertial>
  <visual>
    <origin xyz="0.0323 0.091705 -0.089446" rpy="0 0 0"/>
    <geometry>
      <mesh filename="package://robocop_description/meshes/soportePantalla_v11_1.stl" scale="0.001 0.001 0.001"/>
    </geometry>
    <material name="plstico_mate_verde"/>
  </visual>
  <collision>
    <origin xyz="0.0323 0.091705 -0.089446" rpy="0 0 0"/>
    <geometry>
      <mesh filename="package://robocop_description/meshes/soportePantalla_v11_1.stl" scale="0.001 0.001 0.001"/>
    </geometry>
  </collision>
</link>

<link name="pantallaTouch_v1_1">
  <inertial>
    <origin xyz="0.057008775248030316 -0.021370109057047254 -0.03552722997181007" rpy="0 0 0"/>
    <mass value="0.4448049684188369"/>
    <inertia ixx="0.000218" iyy="0.000719" izz="0.00059" ixy="0.0" iyz="-8.6e-05" ixz="0.0"/>
  </inertial>
  <visual>
    <origin xyz="0.0583 0.13788 -0.223781" rpy="0 0 0"/>
    <geometry>
      <mesh filename="package://robocop_description/meshes/pantallaTouch_v1_1.stl" scale="0.001 0.001 0.001"/>
    </geometry>
    <material name="opaque2321138"/>
  </visual>
  <collision>
    <origin xyz="0.0583 0.13788 -0.223781" rpy="0 0 0"/>
    <geometry>
      <mesh filename="package://robocop_description/meshes/pantallaTouch_v1_1.stl" scale="0.001 0.001 0.001"/>
    </geometry>
  </collision>
</link>

<link name="rueda_v2__9__1">
  <inertial>
    <origin xyz="-0.024841634669981155 -3.770514719891871e-08 9.779884919958182e-08" rpy="0 0 0"/>
    <mass value="0.03535675163245145"/>
    <inertia ixx="5e-06" iyy="6e-06" izz="6e-06" ixy="-0.0" iyz="-0.0" ixz="-0.0"/>
  </inertial>
  <visual>
    <origin xyz="0.0793 -0.104667 -0.033913" rpy="0 0 0"/>
    <geometry>
      <mesh filename="package://robocop_description/meshes/rueda_v2__9__1.stl" scale="0.001 0.001 0.001"/>
    </geometry>
    <material name="aluminio_pulido"/>
  </visual>
  <collision>
    <origin xyz="0.0793 -0.104667 -0.033913" rpy="0 0 0"/>
    <geometry>
      <mesh filename="package://robocop_description/meshes/rueda_v2__9__1.stl" scale="0.001 0.001 0.001"/>
    </geometry>
  </collision>
</link>

<link name="rueda_v2__8__1">
  <inertial>
    <origin xyz="-0.02484163466998078 -4.79860167851287e-07 3.294670629823415e-07" rpy="0 0 0"/>
    <mass value="0.03535675163245145"/>
    <inertia ixx="5e-06" iyy="6e-06" izz="6e-06" ixy="-0.0" iyz="-0.0" ixz="-0.0"/>
  </inertial>
  <visual>
    <origin xyz="0.0793 -0.048295 -0.019446" rpy="0 0 0"/>
    <geometry>
      <mesh filename="package://robocop_description/meshes/rueda_v2__8__1.stl" scale="0.001 0.001 0.001"/>
    </geometry>
    <material name="aluminio_pulido"/>
  </visual>
  <collision>
    <origin xyz="0.0793 -0.048295 -0.019446" rpy="0 0 0"/>
    <geometry>
      <mesh filename="package://robocop_description/meshes/rueda_v2__8__1.stl" scale="0.001 0.001 0.001"/>
    </geometry>
  </collision>
</link>

<link name="rueda_v2__7__1">
  <inertial>
    <origin xyz="-0.02484163466997956 -4.798601685970013e-07 3.294670627949914e-07" rpy="0 0 0"/>
    <mass value="0.03535675163245145"/>
    <inertia ixx="5e-06" iyy="6e-06" izz="6e-06" ixy="-0.0" iyz="-0.0" ixz="-0.0"/>
  </inertial>
  <visual>
    <origin xyz="0.0793 0.001705 -0.019446" rpy="0 0 0"/>
    <geometry>
      <mesh filename="package://robocop_description/meshes/rueda_v2__7__1.stl" scale="0.001 0.001 0.001"/>
    </geometry>
    <material name="aluminio_pulido"/>
  </visual>
  <collision>
    <origin xyz="0.0793 0.001705 -0.019446" rpy="0 0 0"/>
    <geometry>
      <mesh filename="package://robocop_description/meshes/rueda_v2__7__1.stl" scale="0.001 0.001 0.001"/>
    </geometry>
  </collision>
</link>

<link name="rueda_v2__6__1">
  <inertial>
    <origin xyz="-0.02484163466997924 -4.798601688643656e-07 3.29467063017036e-07" rpy="0 0 0"/>
    <mass value="0.03535675163245145"/>
    <inertia ixx="5e-06" iyy="6e-06" izz="6e-06" ixy="-0.0" iyz="-0.0" ixz="-0.0"/>
  </inertial>
  <visual>
    <origin xyz="0.0793 0.051705 -0.019446" rpy="0 0 0"/>
    <geometry>
      <mesh filename="package://robocop_description/meshes/rueda_v2__6__1.stl" scale="0.001 0.001 0.001"/>
    </geometry>
    <material name="aluminio_pulido"/>
  </visual>
  <collision>
    <origin xyz="0.0793 0.051705 -0.019446" rpy="0 0 0"/>
    <geometry>
      <mesh filename="package://robocop_description/meshes/rueda_v2__6__1.stl" scale="0.001 0.001 0.001"/>
    </geometry>
  </collision>
</link>

<link name="rueda_v2__5__1">
  <inertial>
    <origin xyz="-0.024841634669977394 -4.798601686839543e-07 3.2946706300662765e-07" rpy="0 0 0"/>
    <mass value="0.03535675163245145"/>
    <inertia ixx="5e-06" iyy="6e-06" izz="6e-06" ixy="-0.0" iyz="-0.0" ixz="-0.0"/>
  </inertial>
  <visual>
    <origin xyz="0.0793 0.101705 -0.032446" rpy="0 0 0"/>
    <geometry>
      <mesh filename="package://robocop_description/meshes/rueda_v2__5__1.stl" scale="0.001 0.001 0.001"/>
    </geometry>
    <material name="aluminio_pulido"/>
  </visual>
  <collision>
    <origin xyz="0.0793 0.101705 -0.032446" rpy="0 0 0"/>
    <geometry>
      <mesh filename="package://robocop_description/meshes/rueda_v2__5__1.stl" scale="0.001 0.001 0.001"/>
    </geometry>
  </collision>
</link>

<link name="rueda_v2__4__1">
  <inertial>
    <origin xyz="0.024841331604199823 7.798481313492367e-08 9.779895947942263e-08" rpy="0 0 0"/>
    <mass value="0.03535675163245145"/>
    <inertia ixx="5e-06" iyy="6e-06" izz="6e-06" ixy="0.0" iyz="0.0" ixz="-0.0"/>
  </inertial>
  <visual>
    <origin xyz="-0.0777 0.108078 -0.033913" rpy="0 0 0"/>
    <geometry>
      <mesh filename="package://robocop_description/meshes/rueda_v2__4__1.stl" scale="0.001 0.001 0.001"/>
    </geometry>
    <material name="aluminio_pulido"/>
  </visual>
  <collision>
    <origin xyz="-0.0777 0.108078 -0.033913" rpy="0 0 0"/>
    <geometry>
      <mesh filename="package://robocop_description/meshes/rueda_v2__4__1.stl" scale="0.001 0.001 0.001"/>
    </geometry>
  </collision>
</link>

<link name="rueda_v2__3__1">
  <inertial>
    <origin xyz="0.024841331604199518 -4.798601671712754e-07 3.2946717271054027e-07" rpy="0 0 0"/>
    <mass value="0.03535675163245145"/>
    <inertia ixx="5e-06" iyy="6e-06" izz="6e-06" ixy="0.0" iyz="0.0" ixz="-0.0"/>
  </inertial>
  <visual>
    <origin xyz="-0.0777 0.051705 -0.019446" rpy="0 0 0"/>
    <geometry>
      <mesh filename="package://robocop_description/meshes/rueda_v2__3__1.stl" scale="0.001 0.001 0.001"/>
    </geometry>
    <material name="aluminio_pulido"/>
  </visual>
  <collision>
    <origin xyz="-0.0777 0.051705 -0.019446" rpy="0 0 0"/>
    <geometry>
      <mesh filename="package://robocop_description/meshes/rueda_v2__3__1.stl" scale="0.001 0.001 0.001"/>
    </geometry>
  </collision>
</link>

<link name="rueda_v2__2__1">
  <inertial>
    <origin xyz="0.024841331604198866 -4.798601663451134e-07 3.2946717246420953e-07" rpy="0 0 0"/>
    <mass value="0.03535675163245145"/>
    <inertia ixx="5e-06" iyy="6e-06" izz="6e-06" ixy="0.0" iyz="0.0" ixz="-0.0"/>
  </inertial>
  <visual>
    <origin xyz="-0.0777 0.001705 -0.019446" rpy="0 0 0"/>
    <geometry>
      <mesh filename="package://robocop_description/meshes/rueda_v2__2__1.stl" scale="0.001 0.001 0.001"/>
    </geometry>
    <material name="aluminio_pulido"/>
  </visual>
  <collision>
    <origin xyz="-0.0777 0.001705 -0.019446" rpy="0 0 0"/>
    <geometry>
      <mesh filename="package://robocop_description/meshes/rueda_v2__2__1.stl" scale="0.001 0.001 0.001"/>
    </geometry>
  </collision>
</link>

<link name="rueda_v2__1__1">
  <inertial>
    <origin xyz="0.02484133160419831 -4.798601659430912e-07 3.2946717221440935e-07" rpy="0 0 0"/>
    <mass value="0.03535675163245145"/>
    <inertia ixx="5e-06" iyy="6e-06" izz="6e-06" ixy="0.0" iyz="0.0" ixz="-0.0"/>
  </inertial>
  <visual>
    <origin xyz="-0.0777 -0.048295 -0.019446" rpy="0 0 0"/>
    <geometry>
      <mesh filename="package://robocop_description/meshes/rueda_v2__1__1.stl" scale="0.001 0.001 0.001"/>
    </geometry>
    <material name="aluminio_pulido"/>
  </visual>
  <collision>
    <origin xyz="-0.0777 -0.048295 -0.019446" rpy="0 0 0"/>
    <geometry>
      <mesh filename="package://robocop_description/meshes/rueda_v2__1__1.stl" scale="0.001 0.001 0.001"/>
    </geometry>
  </collision>
</link>

<link name="rueda_v2_1">
  <inertial>
    <origin xyz="0.024841331604196965 -4.798601649924628e-07 3.294671725578846e-07" rpy="0 0 0"/>
    <mass value="0.03535675163245145"/>
    <inertia ixx="5e-06" iyy="6e-06" izz="6e-06" ixy="0.0" iyz="0.0" ixz="-0.0"/>
  </inertial>
  <visual>
    <origin xyz="-0.0777 -0.098295 -0.032446" rpy="0 0 0"/>
    <geometry>
      <mesh filename="package://robocop_description/meshes/rueda_v2_1.stl" scale="0.001 0.001 0.001"/>
    </geometry>
    <material name="aluminio_pulido"/>
  </visual>
  <collision>
    <origin xyz="-0.0777 -0.098295 -0.032446" rpy="0 0 0"/>
    <geometry>
      <mesh filename="package://robocop_description/meshes/rueda_v2_1.stl" scale="0.001 0.001 0.001"/>
    </geometry>
  </collision>
</link>

<link name="Lidar_LD19_v1_1">
  <inertial>
    <origin xyz="-1.515328908376773e-07 -0.02912043203405939 0.01512468619072252" rpy="0 0 0"/>
    <mass value="0.27663941043418167"/>
    <inertia ixx="5.1e-05" iyy="5.1e-05" izz="4.9e-05" ixy="-0.0" iyz="0.0" ixz="0.0"/>
  </inertial>
  <visual>
    <origin xyz="0.0013 -0.060295 -0.157446" rpy="0 0 0"/>
    <geometry>
      <mesh filename="package://robocop_description/meshes/Lidar_LD19_v1_1.stl" scale="0.001 0.001 0.001"/>
    </geometry>
    <material name="plstico_brillante_negro"/>
  </visual>
  <collision>
    <origin xyz="0.0013 -0.060295 -0.157446" rpy="0 0 0"/>
    <geometry>
      <mesh filename="package://robocop_description/meshes/Lidar_LD19_v1_1.stl" scale="0.001 0.001 0.001"/>
    </geometry>
  </collision>
</link>

<link name="Led_v1_1">
  <inertial>
    <origin xyz="0.03999984846710794 0.001074189961974753 -0.0149996705328838" rpy="0 0 0"/>
    <mass value="0.022778085600810485"/>
    <inertia ixx="2e-06" iyy="5e-06" izz="3e-06" ixy="-0.0" iyz="0.0" ixz="0.0"/>
  </inertial>
  <visual>
    <origin xyz="0.0013 -0.098295 -0.084446" rpy="0 0 0"/>
    <geometry>
      <mesh filename="package://robocop_description/meshes/Led_v1_1.stl" scale="0.001 0.001 0.001"/>
    </geometry>
    <material name="aluminio_anodizado_rugoso_gris"/>
  </visual>
  <collision>
    <origin xyz="0.0013 -0.098295 -0.084446" rpy="0 0 0"/>
    <geometry>
      <mesh filename="package://robocop_description/meshes/Led_v1_1.stl" scale="0.001 0.001 0.001"/>
    </geometry>
  </collision>
</link>

<link name="Led_v1__1__1">
  <inertial>
    <origin xyz="-0.040000151532891486 0.0010741899619747253 -0.0149996705328838" rpy="0 0 0"/>
    <mass value="0.022778085600810485"/>
    <inertia ixx="2e-06" iyy="5e-06" izz="3e-06" ixy="-0.0" iyz="0.0" ixz="0.0"/>
  </inertial>
  <visual>
    <origin xyz="0.0013 -0.098295 -0.084446" rpy="0 0 0"/>
    <geometry>
      <mesh filename="package://robocop_description/meshes/Led_v1__1__1.stl" scale="0.001 0.001 0.001"/>
    </geometry>
    <material name="aluminio_anodizado_rugoso_gris"/>
  </visual>
  <collision>
    <origin xyz="0.0013 -0.098295 -0.084446" rpy="0 0 0"/>
    <geometry>
      <mesh filename="package://robocop_description/meshes/Led_v1__1__1.stl" scale="0.001 0.001 0.001"/>
    </geometry>
  </collision>
</link>

<joint name="Rigida1" type="fixed">
  <origin xyz="-0.0323 0.088295 0.089446" rpy="0 0 0"/>
  <parent link="base_link"/>
  <child link="soporteCamara_v2_1"/>
</joint>

<joint name="Rigida2" type="fixed">
  <origin xyz="0.031 0.075325 0.008466" rpy="0 0 0"/>
  <parent link="soporteCamara_v2_1"/>
  <child link="depthCamera_v1_1"/>
</joint>

<joint name="Rigida3" type="fixed">
  <origin xyz="-0.077 -0.056705 0.089446" rpy="0 0 0"/>
  <parent link="base_link"/>
  <child link="soporteElectronica_v7_1"/>
</joint>

<joint name="Rigida5" type="fixed">
  <origin xyz="-0.0688 0.088295 0.084446" rpy="0 0 0"/>
  <parent link="base_link"/>
  <child link="basePrincipal_v4_1"/>
</joint>

<joint name="Rigida6" type="fixed">
  <origin xyz="-0.0075 -0.09 -0.002" rpy="0 0 0"/>
  <parent link="basePrincipal_v4_1"/>
  <child link="baseRuedas_v3__1__1"/>
</joint>

<joint name="Rigida7" type="fixed">
  <origin xyz="0.1425 -0.09 -0.002" rpy="0 0 0"/>
  <parent link="basePrincipal_v4_1"/>
  <child link="baseRuedas_v3_1"/>
</joint>

<joint name="Rigida8" type="fixed">
  <origin xyz="-0.0323 -0.091705 0.089446" rpy="0 0 0"/>
  <parent link="base_link"/>
  <child link="soportePantalla_v11_1"/>
</joint>

<joint name="Rigida9" type="fixed">
  <origin xyz="-0.026 -0.046175 0.134335" rpy="0 0 0"/>
  <parent link="soportePantalla_v11_1"/>
  <child link="pantallaTouch_v1_1"/>
</joint>

<joint name="ruedaIzquierda1" type="continuous">
  <origin xyz="-0.003 0.106372 -0.048533" rpy="0 0 0"/>
  <parent link="baseRuedas_v3__1__1"/>
  <child link="rueda_v2__9__1"/>
  <axis xyz="-1.0 0.0 0.0"/>
</joint>

<joint name="ruedaIzquierda2" type="continuous">
  <origin xyz="-0.003 0.05 -0.063" rpy="0 0 0"/>
  <parent link="baseRuedas_v3__1__1"/>
  <child link="rueda_v2__8__1"/>
  <axis xyz="-1.0 0.0 0.0"/>
</joint>

<joint name="ruedaIzquierda3" type="continuous">
  <origin xyz="-0.003 0.0 -0.063" rpy="0 0 0"/>
  <parent link="baseRuedas_v3__1__1"/>
  <child link="rueda_v2__7__1"/>
  <axis xyz="-1.0 0.0 0.0"/>
</joint>

<joint name="ruedaIzquierda4" type="continuous">
  <origin xyz="-0.003 -0.05 -0.063" rpy="0 0 0"/>
  <parent link="baseRuedas_v3__1__1"/>
  <child link="rueda_v2__6__1"/>
  <axis xyz="-1.0 0.0 0.0"/>
</joint>

<joint name="ruedaIzquierda5" type="continuous">
  <origin xyz="-0.003 -0.1 -0.05" rpy="0 0 0"/>
  <parent link="baseRuedas_v3__1__1"/>
  <child link="rueda_v2__5__1"/>
  <axis xyz="-1.0 0.0 0.0"/>
</joint>

<joint name="ruedaDerecha5" type="continuous">
  <origin xyz="0.004 -0.106373 -0.048533" rpy="0 0 0"/>
  <parent link="baseRuedas_v3_1"/>
  <child link="rueda_v2__4__1"/>
  <axis xyz="1.0 0.0 0.0"/>
</joint>

<joint name="ruedaDerecha4" type="continuous">
  <origin xyz="0.004 -0.05 -0.063" rpy="0 0 0"/>
  <parent link="baseRuedas_v3_1"/>
  <child link="rueda_v2__3__1"/>
  <axis xyz="1.0 0.0 0.0"/>
</joint>

<joint name="ruedaDerecha3" type="continuous">
  <origin xyz="0.004 0.0 -0.063" rpy="0 0 0"/>
  <parent link="baseRuedas_v3_1"/>
  <child link="rueda_v2__2__1"/>
  <axis xyz="-1.0 -0.0 0.0"/>
</joint>

<joint name="ruedaDerecha2" type="continuous">
  <origin xyz="0.004 0.05 -0.063" rpy="0 0 0"/>
  <parent link="baseRuedas_v3_1"/>
  <child link="rueda_v2__1__1"/>
  <axis xyz="1.0 0.0 0.0"/>
</joint>

<joint name="ruedaDerecha1" type="continuous">
  <origin xyz="0.004 0.1 -0.05" rpy="0 0 0"/>
  <parent link="baseRuedas_v3_1"/>
  <child link="rueda_v2_1"/>
  <axis xyz="1.0 0.0 0.0"/>
</joint>

<joint name="R\EDgida94" type="fixed">
  <origin xyz="0.0757 0.117 0.068" rpy="0 0 0"/>
  <parent link="soporteElectronica_v7_1"/>
  <child link="Lidar_LD19_v1_1"/>
</joint>

<joint name="Rigida95" type="fixed">
  <origin xyz="-0.0013 0.098295 0.084446" rpy="0 0 0"/>
  <parent link="base_link"/>
  <child link="Led_v1_1"/>
</joint>

<joint name="Rigida96" type="fixed">
  <origin xyz="-0.0013 0.098295 0.084446" rpy="0 0 0"/>
  <parent link="base_link"/>
  <child link="Led_v1__1__1"/>
</joint>

</robot>