<?xml version="1.0" ?>
<robot name="robocop" xmlns:xacro="http://www.ros.org/wiki/xacro">


<xacro:include filename="$(find robocop_description)/urdf/materials.xacro" />
<xacro:include filename="$(find robocop_description)/urdf/robocop.trans" />

<xacro:include filename="$(find robocop_description)/gazebo/robocop_materials.gazebo" />
<xacro:include filename="$(find robocop_description)/gazebo/robocop_physics.gazebo" />
<xacro:include filename="$(find robocop_description)/gazebo/robocop_plugins.gazebo" />

<link name="base_link">
  <inertial>
    <origin xyz="-0.00015252878117210557 0.0011495201398277505 0.08695702362938718" rpy="0 0 0"/>
    <mass value="0.5188659614992409"/>
    <inertia ixx="0.001389" iyy="0.002526" izz="0.003913" ixy="0.0" iyz="0.0" ixz="0.0"/>
  </inertial>
  <visual>
    <origin xyz="0 0 0" rpy="0 0 0"/>
    <geometry>
      <mesh filename="package://robocop_description/meshes/base_link.stl" scale="0.001 0.001 0.001"/>
    </geometry>
    <material name="plstico_mate_verde"/>
  </visual>
  <collision>
    <origin xyz="0 0 0" rpy="0 0 0"/>
    <geometry>
      <mesh filename="package://robocop_description/meshes/base_link.stl" scale="0.001 0.001 0.001"/>
    </geometry>
  </collision>
</link>

<link name="soporteCamara_v2_1">
  <inertial>
    <origin xyz="0.033096700645355887 -0.031000479859321393 0.0028238611176841927" rpy="0 0 0"/>
    <mass value="0.30666683235154446"/>
    <inertia ixx="0.000189" iyy="0.000213" izz="0.0004" ixy="-0.0" iyz="-0.0" ixz="-4e-06"/>
  </inertial>
  <visual>
    <origin xyz="-0.089845 -0.03215 -0.089446" rpy="0 0 0"/>
    <geometry>
      <mesh filename="package://robocop_description/meshes/soporteCamara_v2_1.stl" scale="0.001 0.001 0.001"/>
    </geometry>
    <material name="plstico_mate_verde"/>
  </visual>
  <collision>
    <origin xyz="-0.089845 -0.03215 -0.089446" rpy="0 0 0"/>
    <geometry>
      <mesh filename="package://robocop_description/meshes/soporteCamara_v2_1.stl" scale="0.001 0.001 0.001"/>
    </geometry>
  </collision>
</link>

<link name="depthCamera_v1_1">
  <inertial>
    <origin xyz="-0.006184113912021172 -1.3611701263174228e-05 0.014463487875515435" rpy="0 0 0"/>
    <mass value="1.4328263704058224"/>
    <inertia ixx="0.003111" iyy="0.000283" izz="0.00318" ixy="0.0" iyz="0.0" ixz="-5e-06"/>
  </inertial>
  <visual>
    <origin xyz="-0.157196 -0.00115 -0.097274" rpy="0 0 0"/>
    <geometry>
      <mesh filename="package://robocop_description/meshes/depthCamera_v1_1.stl" scale="0.001 0.001 0.001"/>
    </geometry>
    <material name="acero_satinado"/>
  </visual>
  <collision>
    <origin xyz="-0.157196 -0.00115 -0.097274" rpy="0 0 0"/>
    <geometry>
      <mesh filename="package://robocop_description/meshes/depthCamera_v1_1.stl" scale="0.001 0.001 0.001"/>
    </geometry>
  </collision>
</link>

<link name="soporteElectronica_v7_1">
  <inertial>
    <origin xyz="0.0550026777716467 -0.0750539566858314 0.04613612305196782" rpy="0 0 0"/>
    <mass value="1.7280541618979188"/>
    <inertia ixx="0.008802" iyy="0.002669" izz="0.009606" ixy="-0.0" iyz="-2.2e-05" ixz="-0.0"/>
  </inertial>
  <visual>
    <origin xyz="0.055155 -0.07685 -0.089446" rpy="0 0 0"/>
    <geometry>
      <mesh filename="package://robocop_description/meshes/soporteElectronica_v7_1.stl" scale="0.001 0.001 0.001"/>
    </geometry>
    <material name="plstico_mate_verde"/>
  </visual>
  <collision>
    <origin xyz="0.055155 -0.07685 -0.089446" rpy="0 0 0"/>
    <geometry>
      <mesh filename="package://robocop_description/meshes/soporteElectronica_v7_1.stl" scale="0.001 0.001 0.001"/>
    </geometry>
  </collision>
</link>

<link name="basePrincipal_v4_1">
  <inertial>
    <origin xyz="-0.10000015153288912 -4.798601768295652e-07 -0.0009996705328831484" rpy="0 0 0"/>
    <mass value="0.44398234905881495"/>
    <inertia ixx="0.000868" iyy="0.001466" izz="0.002334" ixy="0.0" iyz="0.0" ixz="0.0"/>
  </inertial>
  <visual>
    <origin xyz="-0.099845 -0.00115 -0.084446" rpy="0 0 0"/>
    <geometry>
      <mesh filename="package://robocop_description/meshes/basePrincipal_v4_1.stl" scale="0.001 0.001 0.001"/>
    </geometry>
    <material name="aluminio_pulido"/>
  </visual>
  <collision>
    <origin xyz="-0.099845 -0.00115 -0.084446" rpy="0 0 0"/>
    <geometry>
      <mesh filename="package://robocop_description/meshes/basePrincipal_v4_1.stl" scale="0.001 0.001 0.001"/>
    </geometry>
  </collision>
</link>

<link name="baseRuedas_v3__1__1">
  <inertial>
    <origin xyz="-0.00016167785566641627 0.002915310120291753 -0.03517812668147839" rpy="0 0 0"/>
    <mass value="0.25465013251117774"/>
    <inertia ixx="0.000128" iyy="0.001194" izz="0.001072" ixy="0.0" iyz="9e-06" ixz="4e-06"/>
  </inertial>
  <visual>
    <origin xyz="0.000155 -0.07615 -0.082446" rpy="0 0 0"/>
    <geometry>
      <mesh filename="package://robocop_description/meshes/baseRuedas_v3__1__1.stl" scale="0.001 0.001 0.001"/>
    </geometry>
    <material name="aluminio_pulido"/>
  </visual>
  <collision>
    <origin xyz="0.000155 -0.07615 -0.082446" rpy="0 0 0"/>
    <geometry>
      <mesh filename="package://robocop_description/meshes/baseRuedas_v3__1__1.stl" scale="0.001 0.001 0.001"/>
    </geometry>
  </collision>
</link>

<link name="baseRuedas_v3_1">
  <inertial>
    <origin xyz="0.0001613747898826616 -0.0029162698406539483 -0.03517812668147681" rpy="0 0 0"/>
    <mass value="0.2546501325111777"/>
    <inertia ixx="0.000128" iyy="0.001194" izz="0.001072" ixy="0.0" iyz="-9e-06" ixz="-4e-06"/>
  </inertial>
  <visual>
    <origin xyz="0.000155 0.07385 -0.082446" rpy="0 0 0"/>
    <geometry>
      <mesh filename="package://robocop_description/meshes/baseRuedas_v3_1.stl" scale="0.001 0.001 0.001"/>
    </geometry>
    <material name="aluminio_pulido"/>
  </visual>
  <collision>
    <origin xyz="0.000155 0.07385 -0.082446" rpy="0 0 0"/>
    <geometry>
      <mesh filename="package://robocop_description/meshes/baseRuedas_v3_1.stl" scale="0.001 0.001 0.001"/>
    </geometry>
  </collision>
</link>

<link name="soportePantalla_v11_1">
  <inertial>
    <origin xyz="-0.05482012321579245 -0.031024327711935747 0.0416932220450911" rpy="0 0 0"/>
    <mass value="1.4723320792485377"/>
    <inertia ixx="0.003919" iyy="0.003175" izz="0.002641" ixy="1e-06" iyz="-1e-06" ixz="0.000192"/>
  </inertial>
  <visual>
    <origin xyz="0.090155 -0.03215 -0.089446" rpy="0 0 0"/>
    <geometry>
      <mesh filename="package://robocop_description/meshes/soportePantalla_v11_1.stl" scale="0.001 0.001 0.001"/>
    </geometry>
    <material name="plstico_mate_verde"/>
  </visual>
  <collision>
    <origin xyz="0.090155 -0.03215 -0.089446" rpy="0 0 0"/>
    <geometry>
      <mesh filename="package://robocop_description/meshes/soportePantalla_v11_1.stl" scale="0.001 0.001 0.001"/>
    </geometry>
  </collision>
</link>

<link name="pantallaTouch_v1_1">
  <inertial>
    <origin xyz="0.014227140264907762 -5.948022128042757e-05 0.03533424485444281" rpy="0 0 0"/>
    <mass value="0.4448110745769616"/>
    <inertia ixx="0.000719" iyy="0.000218" izz="0.00059" ixy="-0.0" iyz="-0.0" ixz="-8.6e-05"/>
  </inertial>
  <visual>
    <origin xyz="0.172151 -0.00115 -0.152249" rpy="0 0 0"/>
    <geometry>
      <mesh filename="package://robocop_description/meshes/pantallaTouch_v1_1.stl" scale="0.001 0.001 0.001"/>
    </geometry>
    <material name="opaque2321138"/>
  </visual>
  <collision>
    <origin xyz="0.172151 -0.00115 -0.152249" rpy="0 0 0"/>
    <geometry>
      <mesh filename="package://robocop_description/meshes/pantallaTouch_v1_1.stl" scale="0.001 0.001 0.001"/>
    </geometry>
  </collision>
</link>

<link name="rueda_v2__9__1">
  <inertial>
    <origin xyz="2.906220757936673e-07 0.024841003276909218 9.779888714145368e-08" rpy="0 0 0"/>
    <mass value="0.03535675163245143"/>
    <inertia ixx="6e-06" iyy="5e-06" izz="6e-06" ixy="0.0" iyz="0.0" ixz="-0.0"/>
  </inertial>
  <visual>
    <origin xyz="-0.106217 -0.07915 -0.033913" rpy="0 0 0"/>
    <geometry>
      <mesh filename="package://robocop_description/meshes/rueda_v2__9__1.stl" scale="0.001 0.001 0.001"/>
    </geometry>
    <material name="aluminio_pulido"/>
  </visual>
  <collision>
    <origin xyz="-0.106217 -0.07915 -0.033913" rpy="0 0 0"/>
    <geometry>
      <mesh filename="package://robocop_description/meshes/rueda_v2__9__1.stl" scale="0.001 0.001 0.001"/>
    </geometry>
  </collision>
</link>

<link name="rueda_v2__8__1">
  <inertial>
    <origin xyz="-1.5153294408154494e-07 0.024841003276908996 3.2946710029971293e-07" rpy="0 0 0"/>
    <mass value="0.035356751632451444"/>
    <inertia ixx="6e-06" iyy="5e-06" izz="6e-06" ixy="0.0" iyz="0.0" ixz="-0.0"/>
  </inertial>
  <visual>
    <origin xyz="-0.049845 -0.07915 -0.019446" rpy="0 0 0"/>
    <geometry>
      <mesh filename="package://robocop_description/meshes/rueda_v2__8__1.stl" scale="0.001 0.001 0.001"/>
    </geometry>
    <material name="aluminio_pulido"/>
  </visual>
  <collision>
    <origin xyz="-0.049845 -0.07915 -0.019446" rpy="0 0 0"/>
    <geometry>
      <mesh filename="package://robocop_description/meshes/rueda_v2__8__1.stl" scale="0.001 0.001 0.001"/>
    </geometry>
  </collision>
</link>

<link name="rueda_v2__7__1">
  <inertial>
    <origin xyz="-1.51532944086722e-07 0.024841003276907747 3.2946710064665763e-07" rpy="0 0 0"/>
    <mass value="0.03535675163245133"/>
    <inertia ixx="6e-06" iyy="5e-06" izz="6e-06" ixy="0.0" iyz="0.0" ixz="-0.0"/>
  </inertial>
  <visual>
    <origin xyz="0.000155 -0.07915 -0.019446" rpy="0 0 0"/>
    <geometry>
      <mesh filename="package://robocop_description/meshes/rueda_v2__7__1.stl" scale="0.001 0.001 0.001"/>
    </geometry>
    <material name="aluminio_pulido"/>
  </visual>
  <collision>
    <origin xyz="0.000155 -0.07915 -0.019446" rpy="0 0 0"/>
    <geometry>
      <mesh filename="package://robocop_description/meshes/rueda_v2__7__1.stl" scale="0.001 0.001 0.001"/>
    </geometry>
  </collision>
</link>

<link name="rueda_v2__6__1">
  <inertial>
    <origin xyz="-1.5153294388031702e-07 0.024841003276907095 3.294671006501271e-07" rpy="0 0 0"/>
    <mass value="0.035356751632451625"/>
    <inertia ixx="6e-06" iyy="5e-06" izz="6e-06" ixy="0.0" iyz="0.0" ixz="-0.0"/>
  </inertial>
  <visual>
    <origin xyz="0.050155 -0.07915 -0.019446" rpy="0 0 0"/>
    <geometry>
      <mesh filename="package://robocop_description/meshes/rueda_v2__6__1.stl" scale="0.001 0.001 0.001"/>
    </geometry>
    <material name="aluminio_pulido"/>
  </visual>
  <collision>
    <origin xyz="0.050155 -0.07915 -0.019446" rpy="0 0 0"/>
    <geometry>
      <mesh filename="package://robocop_description/meshes/rueda_v2__6__1.stl" scale="0.001 0.001 0.001"/>
    </geometry>
  </collision>
</link>

<link name="rueda_v2__5__1">
  <inertial>
    <origin xyz="-1.515329439011337e-07 0.02484100327690518 3.2946710078890495e-07" rpy="0 0 0"/>
    <mass value="0.035356751632451444"/>
    <inertia ixx="6e-06" iyy="5e-06" izz="6e-06" ixy="0.0" iyz="0.0" ixz="-0.0"/>
  </inertial>
  <visual>
    <origin xyz="0.100155 -0.07915 -0.032446" rpy="0 0 0"/>
    <geometry>
      <mesh filename="package://robocop_description/meshes/rueda_v2__5__1.stl" scale="0.001 0.001 0.001"/>
    </geometry>
    <material name="aluminio_pulido"/>
  </visual>
  <collision>
    <origin xyz="0.100155 -0.07915 -0.032446" rpy="0 0 0"/>
    <geometry>
      <mesh filename="package://robocop_description/meshes/rueda_v2__5__1.stl" scale="0.001 0.001 0.001"/>
    </geometry>
  </collision>
</link>

<link name="rueda_v2__4__1">
  <inertial>
    <origin xyz="4.0631203772345525e-07 -0.024841962997266487 9.7798914786007e-08" rpy="0 0 0"/>
    <mass value="0.0353567516324516"/>
    <inertia ixx="6e-06" iyy="5e-06" izz="6e-06" ixy="-0.0" iyz="-0.0" ixz="-0.0"/>
  </inertial>
  <visual>
    <origin xyz="0.106528 0.07685 -0.033913" rpy="0 0 0"/>
    <geometry>
      <mesh filename="package://robocop_description/meshes/rueda_v2__4__1.stl" scale="0.001 0.001 0.001"/>
    </geometry>
    <material name="aluminio_pulido"/>
  </visual>
  <collision>
    <origin xyz="0.106528 0.07685 -0.033913" rpy="0 0 0"/>
    <geometry>
      <mesh filename="package://robocop_description/meshes/rueda_v2__4__1.stl" scale="0.001 0.001 0.001"/>
    </geometry>
  </collision>
</link>

<link name="rueda_v2__3__1">
  <inertial>
    <origin xyz="-1.5153294249253824e-07 -0.024841962997268097 3.2946712819406643e-07" rpy="0 0 0"/>
    <mass value="0.03535675163245149"/>
    <inertia ixx="6e-06" iyy="5e-06" izz="6e-06" ixy="-0.0" iyz="-0.0" ixz="-0.0"/>
  </inertial>
  <visual>
    <origin xyz="0.050155 0.07685 -0.019446" rpy="0 0 0"/>
    <geometry>
      <mesh filename="package://robocop_description/meshes/rueda_v2__3__1.stl" scale="0.001 0.001 0.001"/>
    </geometry>
    <material name="aluminio_pulido"/>
  </visual>
  <collision>
    <origin xyz="0.050155 0.07685 -0.019446" rpy="0 0 0"/>
    <geometry>
      <mesh filename="package://robocop_description/meshes/rueda_v2__3__1.stl" scale="0.001 0.001 0.001"/>
    </geometry>
  </collision>
</link>

<link name="rueda_v2__2__1">
  <inertial>
    <origin xyz="-1.515329426141044e-07 -0.024841962997269235 3.2946712833631375e-07" rpy="0 0 0"/>
    <mass value="0.03535675163245141"/>
    <inertia ixx="6e-06" iyy="5e-06" izz="6e-06" ixy="-0.0" iyz="-0.0" ixz="-0.0"/>
  </inertial>
  <visual>
    <origin xyz="0.000155 0.07685 -0.019446" rpy="0 0 0"/>
    <geometry>
      <mesh filename="package://robocop_description/meshes/rueda_v2__2__1.stl" scale="0.001 0.001 0.001"/>
    </geometry>
    <material name="aluminio_pulido"/>
  </visual>
  <collision>
    <origin xyz="0.000155 0.07685 -0.019446" rpy="0 0 0"/>
    <geometry>
      <mesh filename="package://robocop_description/meshes/rueda_v2__2__1.stl" scale="0.001 0.001 0.001"/>
    </geometry>
  </collision>
</link>

<link name="rueda_v2__1__1">
  <inertial>
    <origin xyz="-1.5153294268682727e-07 -0.024841962997270428 3.2946712844039716e-07" rpy="0 0 0"/>
    <mass value="0.03535675163245155"/>
    <inertia ixx="6e-06" iyy="5e-06" izz="6e-06" ixy="-0.0" iyz="-0.0" ixz="-0.0"/>
  </inertial>
  <visual>
    <origin xyz="-0.049845 0.07685 -0.019446" rpy="0 0 0"/>
    <geometry>
      <mesh filename="package://robocop_description/meshes/rueda_v2__1__1.stl" scale="0.001 0.001 0.001"/>
    </geometry>
    <material name="aluminio_pulido"/>
  </visual>
  <collision>
    <origin xyz="-0.049845 0.07685 -0.019446" rpy="0 0 0"/>
    <geometry>
      <mesh filename="package://robocop_description/meshes/rueda_v2__1__1.stl" scale="0.001 0.001 0.001"/>
    </geometry>
  </collision>
</link>

<link name="rueda_v2_1">
  <inertial>
    <origin xyz="-1.5153294256886607e-07 -0.024841962997271372 3.2946712832937486e-07" rpy="0 0 0"/>
    <mass value="0.035356751632451416"/>
    <inertia ixx="6e-06" iyy="5e-06" izz="6e-06" ixy="-0.0" iyz="-0.0" ixz="-0.0"/>
  </inertial>
  <visual>
    <origin xyz="-0.099845 0.07685 -0.032446" rpy="0 0 0"/>
    <geometry>
      <mesh filename="package://robocop_description/meshes/rueda_v2_1.stl" scale="0.001 0.001 0.001"/>
    </geometry>
    <material name="aluminio_pulido"/>
  </visual>
  <collision>
    <origin xyz="-0.099845 0.07685 -0.032446" rpy="0 0 0"/>
    <geometry>
      <mesh filename="package://robocop_description/meshes/rueda_v2_1.stl" scale="0.001 0.001 0.001"/>
    </geometry>
  </collision>
</link>

<link name="Lidar_LD19_v1_1">
  <inertial>
    <origin xyz="-0.025000151532890494 0.004119472313699195 0.01512468619072252" rpy="0 0 0"/>
    <mass value="0.2766394104341817"/>
    <inertia ixx="5.1e-05" iyy="5.1e-05" izz="4.9e-05" ixy="0.0" iyz="-0.0" ixz="0.0"/>
  </inertial>
  <visual>
    <origin xyz="-0.061845 -0.00115 -0.157446" rpy="0 0 0"/>
    <geometry>
      <mesh filename="package://robocop_description/meshes/Lidar_LD19_v1_1.stl" scale="0.001 0.001 0.001"/>
    </geometry>
    <material name="plstico_brillante_negro"/>
  </visual>
  <collision>
    <origin xyz="-0.061845 -0.00115 -0.157446" rpy="0 0 0"/>
    <geometry>
      <mesh filename="package://robocop_description/meshes/Lidar_LD19_v1_1.stl" scale="0.001 0.001 0.001"/>
    </geometry>
  </collision>
</link>

<joint name="Rigida1" type="fixed">
  <origin xyz="0.089845 0.03215 0.089446" rpy="0 0 0"/>
  <parent link="base_link"/>
  <child link="soporteCamara_v2_1"/>
</joint>

<joint name="Rigida2" type="fixed">
  <origin xyz="0.067351 -0.031 0.007828" rpy="0 0 0"/>
  <parent link="soporteCamara_v2_1"/>
  <child link="depthCamera_v1_1"/>
</joint>

<joint name="Rigida3" type="fixed">
  <origin xyz="-0.055155 0.07685 0.089446" rpy="0 0 0"/>
  <parent link="base_link"/>
  <child link="soporteElectronica_v7_1"/>
</joint>

<joint name="Rigida5" type="fixed">
  <origin xyz="0.099845 0.00115 0.084446" rpy="0 0 0"/>
  <parent link="base_link"/>
  <child link="basePrincipal_v4_1"/>
</joint>

<joint name="Rigida6" type="fixed">
  <origin xyz="-0.1 0.075 -0.002" rpy="0 0 0"/>
  <parent link="basePrincipal_v4_1"/>
  <child link="baseRuedas_v3__1__1"/>
</joint>

<joint name="Rigida7" type="fixed">
  <origin xyz="-0.1 -0.075 -0.002" rpy="0 0 0"/>
  <parent link="basePrincipal_v4_1"/>
  <child link="baseRuedas_v3_1"/>
</joint>

<joint name="Rigida8" type="fixed">
  <origin xyz="-0.090155 0.03215 0.089446" rpy="0 0 0"/>
  <parent link="base_link"/>
  <child link="soportePantalla_v11_1"/>
</joint>

<joint name="Rigida9" type="fixed">
  <origin xyz="-0.081996 -0.031 0.062803" rpy="0 0 0"/>
  <parent link="soportePantalla_v11_1"/>
  <child link="pantallaTouch_v1_1"/>
</joint>

<joint name="ruedaIzquierda1" type="continuous">
  <origin xyz="0.106372 0.003 -0.048533" rpy="0 0 0"/>
  <parent link="baseRuedas_v3__1__1"/>
  <child link="rueda_v2__9__1"/>
  <axis xyz="-0.0 1.0 0.0"/>
</joint>

<joint name="ruedaIzquierda2" type="continuous">
  <origin xyz="0.05 0.003 -0.063" rpy="0 0 0"/>
  <parent link="baseRuedas_v3__1__1"/>
  <child link="rueda_v2__8__1"/>
  <axis xyz="-0.0 1.0 0.0"/>
</joint>

<joint name="ruedaIzquierda3" type="continuous">
  <origin xyz="0.0 0.003 -0.063" rpy="0 0 0"/>
  <parent link="baseRuedas_v3__1__1"/>
  <child link="rueda_v2__7__1"/>
  <axis xyz="-0.0 1.0 0.0"/>
</joint>

<joint name="ruedaIzquierda4" type="continuous">
  <origin xyz="-0.05 0.003 -0.063" rpy="0 0 0"/>
  <parent link="baseRuedas_v3__1__1"/>
  <child link="rueda_v2__6__1"/>
  <axis xyz="-0.0 1.0 0.0"/>
</joint>

<joint name="ruedaIzquierda5" type="continuous">
  <origin xyz="-0.1 0.003 -0.05" rpy="0 0 0"/>
  <parent link="baseRuedas_v3__1__1"/>
  <child link="rueda_v2__5__1"/>
  <axis xyz="-0.0 1.0 0.0"/>
</joint>

<joint name="ruedaDerecha5" type="continuous">
  <origin xyz="-0.106373 -0.003 -0.048533" rpy="0 0 0"/>
  <parent link="baseRuedas_v3_1"/>
  <child link="rueda_v2__4__1"/>
  <axis xyz="-0.0 -1.0 0.0"/>
</joint>

<joint name="ruedaDerecha4" type="continuous">
  <origin xyz="-0.05 -0.003 -0.063" rpy="0 0 0"/>
  <parent link="baseRuedas_v3_1"/>
  <child link="rueda_v2__3__1"/>
  <axis xyz="-0.0 -1.0 0.0"/>
</joint>

<joint name="ruedaDerecha3" type="continuous">
  <origin xyz="0.0 -0.003 -0.063" rpy="0 0 0"/>
  <parent link="baseRuedas_v3_1"/>
  <child link="rueda_v2__2__1"/>
  <axis xyz="-0.0 -1.0 0.0"/>
</joint>

<joint name="ruedaDerecha2" type="continuous">
  <origin xyz="0.05 -0.003 -0.063" rpy="0 0 0"/>
  <parent link="baseRuedas_v3_1"/>
  <child link="rueda_v2__1__1"/>
  <axis xyz="-0.0 -1.0 0.0"/>
</joint>

<joint name="ruedaDerecha1" type="continuous">
  <origin xyz="0.1 -0.003 -0.05" rpy="0 0 0"/>
  <parent link="baseRuedas_v3_1"/>
  <child link="rueda_v2_1"/>
  <axis xyz="-0.0 -1.0 0.0"/>
</joint>

<joint name="R�gida94" type="fixed">
  <origin xyz="0.117 -0.0757 0.068" rpy="0 0 0"/>
  <parent link="soporteElectronica_v7_1"/>
  <child link="Lidar_LD19_v1_1"/>
</joint>

</robot>
